<robot name = "robot">
    <link name="Head">
        <inertial>
            <origin xyz="0 0 0.5" rpy="0 0 0"/>
            <mass value="1" />
            <inertia ixx="100" ixy="0" ixz="0" iyy="100" iyz="0" izz="100" />
        </inertial>
        <visual>
            <origin xyz="0 0 0.5" rpy="0 0 0"/>
            <geometry>
             <sphere radius="1" />
            </geometry>
            <material name="Cyan">
                <color rgba="0 1.0 1.0 1.0"/>
            </material>
        </visual>
        <collision>
            <origin xyz="0 0 0.5" rpy="0 0 0"/>
            <geometry>
             <sphere radius="1" />
            </geometry>
        </collision>
    </link>
    <joint name="Head_link0" type="revolute">
       <parent link="Head"/>
       <child  link="link0"/>
       <origin rpy="0 0 0" xyz="1 0 0" />
       <axis xyz="0 1 0"/>
       <limit effort="0.0" lower="-3.14159" upper="3.14159" velocity="0.0"/>
    </joint>
    <link name="link0">
        <inertial>
            <origin xyz="0.9534511440060804 0 0.5" rpy="0 0 0"/>
            <mass value="1" />
            <inertia ixx="100" ixy="0" ixz="0" iyy="100" iyz="0" izz="100" />
        </inertial>
        <visual>
            <origin xyz="0.9534511440060804 0 0.5" rpy="0 0 0"/>
            <geometry>
             <sphere radius="1.9069022880121609" />
            </geometry>
            <material name="Cyan">
                <color rgba="0 1.0 1.0 1.0"/>
            </material>
        </visual>
        <collision>
            <origin xyz="0.9534511440060804 0 0.5" rpy="0 0 0"/>
            <geometry>
             <sphere radius="1.9069022880121609" />
            </geometry>
        </collision>
    </link>
</robot>