<robot name = "robot">
    <link name="link0">
        <inertial>
            <origin xyz="0 0 5" rpy="0 0 0"/>
            <mass value="1" />
            <inertia ixx="100" ixy="0" ixz="0" iyy="100" iyz="0" izz="100" />
        </inertial>
        <visual>
            <origin xyz="0 0 5" rpy="0 0 0"/>
            <geometry>
            <box size="0.5187471549442595 0.33361851301769613 0.8708534894495175" />
            </geometry>
            <material name="Blue">
                <color rgba="0 0 1.0 1.0"/>
            </material>
        </visual>
        <collision>
            <origin xyz="0 0 5" rpy="0 0 0"/>
            <geometry>
            <box size="0.5187471549442595 0.33361851301769613 0.8708534894495175" />
            </geometry>
        </collision>
    </link>
    <joint name="link0_link1" type="revolute">
       <parent link="link0"/>
       <child  link="link1"/>
       <origin rpy="0 0 0" xyz="0.25937357747212975 0 5" />
       <axis xyz="1 1 1"/>
       <limit effort="0.0" lower="-3.14159" upper="3.14159" velocity="0.0"/>
    </joint>
    <link name="link1">
        <inertial>
            <origin xyz="0.17715669487668584 0 0" rpy="0 0 0"/>
            <mass value="1" />
            <inertia ixx="100" ixy="0" ixz="0" iyy="100" iyz="0" izz="100" />
        </inertial>
        <visual>
            <origin xyz="0.17715669487668584 0 0" rpy="0 0 0"/>
            <geometry>
            <box size="0.3543133897533717 0.8239359919540201 0.7146802687023277" />
            </geometry>
            <material name="Blue">
                <color rgba="0 0 1.0 1.0"/>
            </material>
        </visual>
        <collision>
            <origin xyz="0.17715669487668584 0 0" rpy="0 0 0"/>
            <geometry>
            <box size="0.3543133897533717 0.8239359919540201 0.7146802687023277" />
            </geometry>
        </collision>
    </link>
    <joint name="link1_link2" type="revolute">
       <parent link="link1"/>
       <child  link="link2"/>
       <origin rpy="0 0 0" xyz="0.17715669487668584 0 0.35734013435116385" />
       <axis xyz="1 1 1"/>
       <limit effort="0.0" lower="-3.14159" upper="3.14159" velocity="0.0"/>
    </joint>
    <link name="link2">
        <inertial>
            <origin xyz="0 0 0.42479481011737874" rpy="0 0 0"/>
            <mass value="1" />
            <inertia ixx="100" ixy="0" ixz="0" iyy="100" iyz="0" izz="100" />
        </inertial>
        <visual>
            <origin xyz="0 0 0.42479481011737874" rpy="0 0 0"/>
            <geometry>
            <box size="0.6612657984493984 0.447320864598771 0.8495896202347575" />
            </geometry>
            <material name="Green">
                <color rgba="0 1.0 0 1.0"/>
            </material>
        </visual>
        <collision>
            <origin xyz="0 0 0.42479481011737874" rpy="0 0 0"/>
            <geometry>
            <box size="0.6612657984493984 0.447320864598771 0.8495896202347575" />
            </geometry>
        </collision>
    </link>
    <joint name="link2_link3" type="revolute">
       <parent link="link2"/>
       <child  link="link3"/>
       <origin rpy="0 0 0" xyz="0 0 0.8495896202347575" />
       <axis xyz="1 1 1"/>
       <limit effort="0.0" lower="-3.14159" upper="3.14159" velocity="0.0"/>
    </joint>
    <link name="link3">
        <inertial>
            <origin xyz="0 0 0.229991649533542" rpy="0 0 0"/>
            <mass value="1" />
            <inertia ixx="100" ixy="0" ixz="0" iyy="100" iyz="0" izz="100" />
        </inertial>
        <visual>
            <origin xyz="0 0 0.229991649533542" rpy="0 0 0"/>
            <geometry>
            <box size="0.5249830620569577 0.5668819234566724 0.459983299067084" />
            </geometry>
            <material name="Green">
                <color rgba="0 1.0 0 1.0"/>
            </material>
        </visual>
        <collision>
            <origin xyz="0 0 0.229991649533542" rpy="0 0 0"/>
            <geometry>
            <box size="0.5249830620569577 0.5668819234566724 0.459983299067084" />
            </geometry>
        </collision>
    </link>
    <joint name="link3_link4" type="revolute">
       <parent link="link3"/>
       <child  link="link4"/>
       <origin rpy="0 0 0" xyz="0 0.2834409617283362 0.229991649533542" />
       <axis xyz="1 1 1"/>
       <limit effort="0.0" lower="-3.14159" upper="3.14159" velocity="0.0"/>
    </joint>
    <link name="link4">
        <inertial>
            <origin xyz="0 0.38257341481146434 0" rpy="0 0 0"/>
            <mass value="1" />
            <inertia ixx="100" ixy="0" ixz="0" iyy="100" iyz="0" izz="100" />
        </inertial>
        <visual>
            <origin xyz="0 0.38257341481146434 0" rpy="0 0 0"/>
            <geometry>
            <box size="0.4077547623083875 0.7651468296229287 0.4549747946563944" />
            </geometry>
            <material name="Green">
                <color rgba="0 1.0 0 1.0"/>
            </material>
        </visual>
        <collision>
            <origin xyz="0 0.38257341481146434 0" rpy="0 0 0"/>
            <geometry>
            <box size="0.4077547623083875 0.7651468296229287 0.4549747946563944" />
            </geometry>
        </collision>
    </link>
    <joint name="link4_link5" type="revolute">
       <parent link="link4"/>
       <child  link="link5"/>
       <origin rpy="0 0 0" xyz="0.20387738115419374 0.38257341481146434 0" />
       <axis xyz="1 1 1"/>
       <limit effort="0.0" lower="-3.14159" upper="3.14159" velocity="0.0"/>
    </joint>
    <link name="link5">
        <inertial>
            <origin xyz="0.20335332930388997 0 0" rpy="0 0 0"/>
            <mass value="1" />
            <inertia ixx="100" ixy="0" ixz="0" iyy="100" iyz="0" izz="100" />
        </inertial>
        <visual>
            <origin xyz="0.20335332930388997 0 0" rpy="0 0 0"/>
            <geometry>
            <box size="0.40670665860777994 0.35641939266111833 0.4569001436676954" />
            </geometry>
            <material name="Blue">
                <color rgba="0 0 1.0 1.0"/>
            </material>
        </visual>
        <collision>
            <origin xyz="0.20335332930388997 0 0" rpy="0 0 0"/>
            <geometry>
            <box size="0.40670665860777994 0.35641939266111833 0.4569001436676954" />
            </geometry>
        </collision>
    </link>
</robot>